<?xml version="1.0"?>
<robot name="xarm_lite">
  <link name="base_link"/>
  <joint name="base_to_arm" type="fixed">
    <parent link="base_link"/>
    <child link="arm_base"/>
    <origin xyz="0 0 0" rpy="0 0 0"/>
  </joint>
  <link name="arm_base">
    <visual>
      <geometry>
        <cylinder radius="0.05" length="0.1"/>
      </geometry>
      <material name="blue">
        <color rgba="0 0 1 1"/>
      </material>
    </visual>
  </link>
  <!-- Simple arm kinematics -->
  <link name="shoulder">
    <visual>
      <geometry>
        <cylinder radius="0.04" length="0.3"/>
      </geometry>
      <material name="red">
        <color rgba="1 0 0 1"/>
      </material>
    </visual>
  </link>
  <joint name="shoulder_joint" type="revolute">
    <parent link="arm_base"/>
    <child link="shoulder"/>
    <origin xyz="0 0 0.1" rpy="0 0 0"/>
    <axis xyz="0 1 0"/>
    <limit lower="-3.14" upper="3.14" effort="10" velocity="1"/>
  </joint>
  <link name="elbow">
    <visual>
      <geometry>
        <cylinder radius="0.03" length="0.25"/>
      </geometry>
      <material name="green">
        <color rgba="0 1 0 1"/>
      </material>
    </visual>
  </link>
  <joint name="elbow_joint" type="revolute">
    <parent link="shoulder"/>
    <child link="elbow"/>
    <origin xyz="0 0 0.3" rpy="0 0 0"/>
    <axis xyz="0 1 0"/>
    <limit lower="-1.57" upper="1.57" effort="10" velocity="1"/>
  </joint>
  <link name="wrist">
    <visual>
      <geometry>
        <cylinder radius="0.02" length="0.2"/>
      </geometry>
      <material name="blue">
        <color rgba="0 0 1 1"/>
      </material>
    </visual>
  </link>
  <joint name="wrist_joint" type="revolute">
    <parent link="elbow"/>
    <child link="wrist"/>
    <origin xyz="0 0 0.25" rpy="0 0 0"/>
    <axis xyz="0 1 0"/>
    <limit lower="-3.14" upper="3.14" effort="10" velocity="1"/>
  </joint>
  <link name="end_effector">
    <visual>
      <geometry>
        <box size="0.05 0.05 0.05"/>
      </geometry>
      <material name="gray">
        <color rgba="0.5 0.5 0.5 1"/>
      </material>
    </visual>
  </link>
  <joint name="ee_joint" type="fixed">
    <parent link="wrist"/>
    <child link="end_effector"/>
    <origin xyz="0 0 0.2" rpy="0 0 0"/>
  </joint>
  <!-- Extruder placeholder -->
  <link name="extruder"/>
  <joint name="extruder_joint" type="fixed">
    <parent link="end_effector"/>
    <child link="extruder"/>
    <origin xyz="0 0 0.05" rpy="0 0 0"/>
  </joint>
</robot>
